[0m14:02:58.364961 [debug] [MainThread]: Sending event: {'category': 'dbt', 'action': 'invocation', 'label': 'start', 'context': [<snowplow_tracker.self_describing_json.SelfDescribingJson object at 0x000002747FB17E60>, <snowplow_tracker.self_describing_json.SelfDescribingJson object at 0x0000027402C00980>, <snowplow_tracker.self_describing_json.SelfDescribingJson object at 0x0000027402C03AD0>]}


============================== 14:02:58.369182 | 36bdf055-7b44-4f15-b04f-ea650358f6f2 ==============================
[0m14:02:58.369182 [info ] [MainThread]: Running with dbt=1.10.1
[0m14:02:58.370191 [debug] [MainThread]: running dbt with arguments {'printer_width': '80', 'indirect_selection': 'eager', 'log_cache_events': 'False', 'write_json': 'True', 'partial_parse': 'True', 'cache_selected_only': 'False', 'warn_error': 'None', 'fail_fast': 'False', 'debug': 'False', 'log_path': 'logs', 'version_check': 'True', 'profiles_dir': 'C:\\Users\\Vansh\\.dbt', 'use_colors': 'True', 'use_experimental_parser': 'False', 'no_print': 'None', 'quiet': 'False', 'empty': 'False', 'log_format': 'default', 'invocation_command': 'dbt snapshot', 'introspect': 'True', 'warn_error_options': 'WarnErrorOptionsV2(error=[], warn=[], silence=[])', 'target_path': 'None', 'static_parser': 'True', 'send_anonymous_usage_stats': 'True'}
[0m14:02:58.372225 [error] [MainThread]: Encountered an error:
Runtime Error
  No dbt_project.yml found at expected path C:\Users\Vansh\Machine Learning\dataChatbot\dbt_project.yml
  Verify that each entry within packages.yml (and their transitive dependencies) contains a file named dbt_project.yml
  
[0m14:02:58.372225 [debug] [MainThread]: Command `dbt snapshot` failed at 14:02:58.372225 after 0.14 seconds
[0m14:02:58.373291 [debug] [MainThread]: Sending event: {'category': 'dbt', 'action': 'invocation', 'label': 'end', 'context': [<snowplow_tracker.self_describing_json.SelfDescribingJson object at 0x000002747FB17E60>, <snowplow_tracker.self_describing_json.SelfDescribingJson object at 0x0000027401ECC9B0>, <snowplow_tracker.self_describing_json.SelfDescribingJson object at 0x0000027402FCA630>]}
[0m14:02:58.373291 [debug] [MainThread]: Flushing usage events
[0m14:02:59.879990 [debug] [MainThread]: An error was encountered while trying to flush usage events
